Workbook

Sheet Read Me
A1: Baumarkt-Buddy – Release Planning Workbook
A2: Source: requirements/baumarkt-buddy-product-requirements.md v1.0 · Draft 23 Oct 2026 · Owner: Quality & Responsible AI
B5: Purpose
B6: Plan the product in 3 releases: select functional, safety, non-functional and data requirements per release, the design components needed to build them, and the release-blocking tests that verify each release.
B8: Releases (course scope)
B9: R1 – MVP / Pitch demo | C9: 2-week sprint (19 Oct – ~1 Nov 2026). One safe end-to-end flow: text/template -> questions -> validated shopping list with aisle. Built and tested.
B10: R2 – Extended MVP | C10: Planned (roadmap only). More templates, explanations, alternatives, owned items, offline checklist, assembly guide.
B11: R3 – Pilot-ready | C11: Planned (roadmap only). Photo and voice entry, real store data, store search, scanner, associate hand-off, monitoring.
B12: Beyond | C12: Not planned in the 3 releases (reservation, multi-retailer).
B14: METHOD 1 – Team selection (bottom-up)
B15: Sheets | C15: M1 Requirements · M1 Design Components · M1 Traceability
B16: Step 1 | C16: Everyone reads M1 Requirements (68 items: 24 FR, 10 SR, 11 NFR, 7 DR, 14 release-blocking tests).
B17: Step 2 | C17: In the team meeting, fill the yellow columns: Team MoSCoW (Must/Should/Could/Won't) and Team release (R1/R2/R3/Beyond).
B18: Step 3 | C18: M1 Design Components then shows automatically which components are needed and in which release (earliest release of any linked requirement).
B19: Step 4 | C19: Use M1 Traceability to check that every selected requirement has its components and that every release-blocking test is in the same release as its feature.
B20: Result | C20: The team's own release plan. Good for discussion and buy-in, but slower and depends on the team's judgement.
B22: METHOD 2 – Claude's proposal (top-down, recommended)
B23: Technique | C23: Goal-driven release slicing with MoSCoW per release + walking skeleton + V-model exit gates.
B24: Step 1 · Release goal | C24: Define ONE goal per release (see above). The goal is the filter for everything else.
B25: Step 2 · MoSCoW per release | C25: For each requirement ask: is it needed for this release's goal? Must = goal fails without it · Should = important, not vital · Could = if time allows · Won't = moved to a later release.
B26: Step 3 · Safety rule | C26: Every safety requirement and release-blocking test that applies to a feature in the release is automatically Must in that release. Safety is never negotiated down.
B27: Step 4 · Walking skeleton | C27: R1 builds a thin slice through ALL 5 architecture layers (UI, orchestrator, AI, deterministic gates, data). Later releases widen layers, not add new ones.
B28: Step 5 · Dependencies | C28: A requirement cannot be earlier than the components and data it needs (e.g. assembly guide needs manufacturer data).
B29: Step 6 · Capacity check | C29: Musts should be about 60 % of the release effort; Should/Could fill the rest. If Musts exceed capacity, reduce scope (e.g. fewer templates), not safety.
B30: Step 7 · Exit gate | C30: A release is done only when its release-blocking tests pass (V&V) and its validation KPI is met (user test).
B31: Sheets | C31: M2 Proposal (one row per requirement with release, MoSCoW, rationale, team accept/change) · M2 Components by Release · M2 Release Plan (counts + gates).
B33: How to use the two methods together
B34: 1) Each member fills Method 1 alone (10 min). 2) Compare with Method 2 in the meeting. 3) Discuss only the rows where they differ. 4) Record the decision in M2 Proposal -> 'Team decision'.
B36: Legend
B37: Yellow cells | C37: Team input (drop-down lists).
B38: Source priority | C38: P0 = MVP mandatory · P1 = pilot · P2 = later · Gate = release-blocking test (as in the requirements file).
B39: Example (Method 1 row) | C39: FR-05 · Team MoSCoW = Must · Team release = R1 · Owner = Quality · Comment = 'max. 3 questions, wall type + load'
B40: Note | C40: FR-02, FR-03, FR-04, FR-24, SR-02, SR-07, SR-10 contain several parts. Method 2 rationale says which part goes into which release.

Sheet M1 Requirements
A1: Method 1 – All requirements (fill yellow columns as a team)
A2: 68 items from requirements v1.0 · filter with the arrows in row 4
A4: ID | B4: Type | C4: Category | D4: Requirement | E4: Acceptance criterion / verification | F4: Source priority | G4: Source § | H4: Related design components | I4: Team MoSCoW | J4: Team release | K4: Owner | L4: Team comment | M4: Release no. (auto)
A5: FR-01 | B5: Functional | C5: Project lifecycle | D5: Create, save, resume and delete a project | E5: Returning user resumes the last confirmed state; deletion status is reported. | F5: P0 | G5: §4 | H5: DC-13, DC-14, DC-15 | M5: =IFERROR(MATCH(J5,{"R1","R2","R3","Beyond"},0),"")
A6: FR-02 | B6: Functional | C6: Project entry | D6: Accept a free-text project description and multiple role-labelled photos | E6: Photo role is explicit (reference, room/installation area, owned item); reference and room photos are not silently treated as the same scene. | F6: P0 | G6: §4 | H6: DC-01, DC-09, DC-17, DC-21 | M6: =IFERROR(MATCH(J6,{"R1","R2","R3","Beyond"},0),"")
A7: FR-03 | B7: Functional | C7: Project entry | D7: Classify project intent and extract candidate objects/visible labels | E7: At least 8 of 10 supported intent prompts are correctly classified in the project benchmark; observations retain source, uncertainty and confirmation status. | F7: P0 | G7: §4 | H7: DC-17, DC-21, DC-02 | M7: =IFERROR(MATCH(J7,{"R1","R2","R3","Beyond"},0),"")
A8: FR-04 | B8: Functional | C8: Clarification & facts | D8: Capture measurements, units, constraints and owned items | E8: Critical dimensions and load are user-confirmed; unit conflicts block product matching; uncertain owned items are not treated as suitable. | F8: P0 | G8: §4 | H8: DC-02, DC-23, DC-29 | M8: =IFERROR(MATCH(J8,{"R1","R2","R3","Beyond"},0),"")
A9: FR-05 | B9: Functional | C9: Clarification & facts | D9: Ask dependency-aware follow-up questions | E9: Ask no more than three at a time; allow skips; missing safety-critical substrate/load facts block final fixing selection. | F9: P0 | G9: §4 | H9: DC-03, DC-18, DC-23, DC-32 | M9: =IFERROR(MATCH(J9,{"R1","R2","R3","Beyond"},0),"")
A10: FR-06 | B10: Functional | C10: Planning | D10: Generate a structured bill of materials (BOM) | E10: Separate materials, consumables, tools and PPE; show role, specification, quantity basis and dependencies; derive quantities from confirmed dimensions; target under 5 seconds for a bounded plan. | F10: P0 | G10: §4 | H10: DC-19, DC-24, DC-32, DC-04 | M10: =IFERROR(MATCH(J10,{"R1","R2","R3","Beyond"},0),"")
A11: FR-07 | B11: Functional | C11: Planning | D11: Reconcile suitable owned items against the BOM | E11: Deduct only confirmed suitable quantities; mark unknown/uncertain items for identification. | F11: P0 | G11: §4 | H11: DC-29, DC-02 | M11: =IFERROR(MATCH(J11,{"R1","R2","R3","Beyond"},0),"")
A12: FR-08 | B12: Functional | C12: Validation | D12: Match exact catalogue products and variants | E12: Each recommended item maps to a catalogue record and identifiable variant; the model cannot invent product names, SKUs or prices. | F12: P0 | G12: §4 | H12: DC-25, DC-24, DC-30 | M12: =IFERROR(MATCH(J12,{"R1","R2","R3","Beyond"},0),"")
A13: FR-09 | B13: Functional | C13: Validation | D13: Validate product and component compatibility | E13: Check relevant dimensions, material, system, pack quantity and manufacturer-supported constraints; retain evidence for each check. | F13: P0 | G13: §4 | H13: DC-24, DC-33, DC-34 | M13: =IFERROR(MATCH(J13,{"R1","R2","R3","Beyond"},0),"")
A14: FR-10 | B14: Functional | C14: Validation | D14: Explain recommendations and unresolved facts | E14: User can see why an item fits, which facts support it and what remains unverified. | F14: P0 | G14: §4 | H14: DC-20, DC-04, DC-34 | M14: =IFERROR(MATCH(J14,{"R1","R2","R3","Beyond"},0),"")
A15: FR-11 | B15: Functional | C15: Shopping | D15: Show price, availability and store information | E15: Display price, tax/pack basis, stock status, source and retrieval time; unknown, stale and out-of-stock are distinct. Mock values are labelled as mock. | F15: P0 | G15: §4 | H15: DC-04, DC-31, DC-35 | M15: =IFERROR(MATCH(J15,{"R1","R2","R3","Beyond"},0),"")
A16: FR-12 | B16: Functional | C16: Shopping | D16: Offer feasible basket options and alternatives | E16: Where supported catalogue alternatives exist, show compatible lower-cost or premium choices; enforce hard constraints and update totals immediately. | F16: P0 | G16: §4 | H16: DC-28, DC-24, DC-04 | M16: =IFERROR(MATCH(J16,{"R1","R2","R3","Beyond"},0),"")
... A70: RB-14 | B70: Release-blocking test | C70: Revalidation | D70: A changed product during shopping triggers revalidation of affected assembly steps. | E70: Test passes = steps invalidated. | F70: Gate | G70: §10 | H70: DC-11, DC-16 | M70: =IFERROR(MATCH(J70,{"R1","R2","R3","Beyond"},0),"")

Sheet M1 Design Components
A1: Method 1 – Design / architecture components
A2: Release needed is calculated from the team's picks in M1 Requirements (earliest release of any linked requirement)
A4: ID | B4: Layer | C4: Component | D4: Type | E4: Responsibility | F4: Must NOT do | G4: # linked requirements | H4: Release needed (from team picks) | I4: Team comment
A5: DC-01 | B5: L1 Presentation | C5: Project entry screen (text + template picker) | D5: UI | E5: Free-text entry and choice of project template; start/resume project | F5: Show results before validation | G5: =COUNTIF('M1 Requirements'!$H$5:$H$70,"*"&A5&"*") -> 2 | H5: =IF(_xlfn.MINIFS('M1 Requirements'!$M$5:$M$70,'M1 Requirements'!$H$5:$H$70,"*"&A5&"*")=0,"not selected",INDEX({"R1","R2","R3","Beyond"},_xlfn.MINIFS('M1 Requirements'!$M$5:$M$70,'M1 Requirements'!$H$5:$H$70,"*"&A5&"*"))) -> not selected
A6: DC-02 | B6: L1 Presentation | C6: Project summary & fact confirmation | D6: UI | E6: Show understood facts with status; user confirms/edits load, dimensions, wall type | F6: Use unconfirmed facts | G6: =COUNTIF('M1 Requirements'!$H$5:$H$70,"*"&A6&"*") -> 5 | H6: =IF(_xlfn.MINIFS('M1 Requirements'!$M$5:$M$70,'M1 Requirements'!$H$5:$H$70,"*"&A6&"*")=0,"not selected",INDEX({"R1","R2","R3","Beyond"},_xlfn.MINIFS('M1 Requirements'!$M$5:$M$70,'M1 Requirements'!$H$5:$H$70,"*"&A6&"*"))) -> not selected
A7: DC-03 | B7: L1 Presentation | C7: Clarification question UI | D7: UI | E7: Show max. 3 questions, allow skip | F7: Ask more than 3 at once | G7: =COUNTIF('M1 Requirements'!$H$5:$H$70,"*"&A7&"*") -> 1 | H7: =IF(_xlfn.MINIFS('M1 Requirements'!$M$5:$M$70,'M1 Requirements'!$H$5:$H$70,"*"&A7&"*")=0,"not selected",INDEX({"R1","R2","R3","Beyond"},_xlfn.MINIFS('M1 Requirements'!$M$5:$M$70,'M1 Requirements'!$H$5:$H$70,"*"&A7&"*"))) -> not selected
A8: DC-04 | B8: L1 Presentation | C8: BOM / shopping list view | D8: UI | E8: Materials, consumables, tools, PPE with quantity basis, price, stock, aisle/shelf, mock & AI labels | F8: Display unvalidated items or invented aisles | G8: =COUNTIF('M1 Requirements'!$H$5:$H$70,"*"&A8&"*") -> 10 | H8: =IF(_xlfn.MINIFS('M1 Requirements'!$M$5:$M$70,'M1 Requirements'!$H$5:$H$70,"*"&A8&"*")=0,"not selected",INDEX({"R1","R2","R3","Beyond"},_xlfn.MINIFS('M1 Requirements'!$M$5:$M$70,'M1 Requirements'!$H$5:$H$70,"*"&A8&"*"))) -> not selected
A9: DC-05 | B9: L1 Presentation | C9: Safety banner & hand-off UI | D9: UI | E9: Refusal, safety-blocked and detector warnings; 'hire a professional / ask staff' | F9: Be dismissible by AI text | G9: =COUNTIF('M1 Requirements'!$H$5:$H$70,"*"&A9&"*") -> 5 | H9: =IF(_xlfn.MINIFS('M1 Requirements'!$M$5:$M$70,'M1 Requirements'!$H$5:$H$70,"*"&A9&"*")=0,"not selected",INDEX({"R1","R2","R3","Beyond"},_xlfn.MINIFS('M1 Requirements'!$M$5:$M$70,'M1 Requirements'!$H$5:$H$70,"*"&A9&"*"))) -> not selected
A10: DC-06 | B10: L1 Presentation | C10: Checklist & offline cache (PWA) | D10: UI | E10: Tick-off list, readable offline, stock marked stale | F10: Claim live stock offline | G10: =COUNTIF('M1 Requirements'!$H$5:$H$70,"*"&A10&"*") -> 2 | H10: =IF(_xlfn.MINIFS('M1 Requirements'!$M$5:$M$70,'M1 Requirements'!$H$5:$H$70,"*"&A10&"*")=0,"not selected",INDEX({"R1","R2","R3","Beyond"},_xlfn.MINIFS('M1 Requirements'!$M$5:$M$70,'M1 Requirements'!$H$5:$H$70,"*"&A10&"*"))) -> not selected
A11: DC-07 | B11: L1 Presentation | C11: Export / share module | D11: UI | E11: Link/PDF export of user-selected info | F11: Share unselected data | G11: =COUNTIF('M1 Requirements'!$H$5:$H$70,"*"&A11&"*") -> 3 | H11: =IF(_xlfn.MINIFS('M1 Requirements'!$M$5:$M$70,'M1 Requirements'!$H$5:$H$70,"*"&A11&"*")=0,"not selected",INDEX({"R1","R2","R3","Beyond"},_xlfn.MINIFS('M1 Requirements'!$M$5:$M$70,'M1 Requirements'!$H$5:$H$70,"*"&A11&"*"))) -> not selected
A12: DC-08 | B12: L1 Presentation | C12: Assembly guide view | D12: UI | E12: Step-by-step guide linked to BOM and reviewed sources | F12: Reference items not in BOM | G12: =COUNTIF('M1 Requirements'!$H$5:$H$70,"*"&A12&"*") -> 2 | H12: =IF(_xlfn.MINIFS('M1 Requirements'!$M$5:$M$70,'M1 Requirements'!$H$5:$H$70,"*"&A12&"*")=0,"not selected",INDEX({"R1","R2","R3","Beyond"},_xlfn.MINIFS('M1 Requirements'!$M$5:$M$70,'M1 Requirements'!$H$5:$H$70,"*"&A12&"*"))) -> not selected
A13: DC-09 | B13: L1 Presentation | C13: Photo capture & role labelling | D13: UI | E13: Upload photos with explicit role | F13: Merge reference and room photos | G13: =COUNTIF('M1 Requirements'!$H$5:$H$70,"*"&A13&"*") -> 2 | H13: =IF(_xlfn.MINIFS('M1 Requirements'!$M$5:$M$70,'M1 Requirements'!$H$5:$H$70,"*"&A13&"*")=0,"not selected",INDEX({"R1","R2","R3","Beyond"},_xlfn.MINIFS('M1 Requirements'!$M$5:$M$70,'M1 Requirements'!$H$5:$H$70,"*"&A13&"*"))) -> not selected
A14: DC-10 | B14: L1 Presentation | C14: Voice input (speech-to-text) | D14: UI | E14: Transcribe speech, show editable transcript | F14: Use spoken values unconfirmed | G14: =COUNTIF('M1 Requirements'!$H$5:$H$70,"*"&A14&"*") -> 1 | H14: =IF(_xlfn.MINIFS('M1 Requirements'!$M$5:$M$70,'M1 Requirements'!$H$5:$H$70,"*"&A14&"*")=0,"not selected",INDEX({"R1","R2","R3","Beyond"},_xlfn.MINIFS('M1 Requirements'!$M$5:$M$70,'M1 Requirements'!$H$5:$H$70,"*"&A14&"*"))) -> not selected
A15: DC-11 | B15: L1 Presentation | C15: Barcode / product scanner | D15: UI | E15: Scan product during shopping, detect mismatch | F15: Accept a different variant silently | G15: =COUNTIF('M1 Requirements'!$H$5:$H$70,"*"&A15&"*") -> 2 | H15: =IF(_xlfn.MINIFS('M1 Requirements'!$M$5:$M$70,'M1 Requirements'!$H$5:$H$70,"*"&A15&"*")=0,"not selected",INDEX({"R1","R2","R3","Beyond"},_xlfn.MINIFS('M1 Requirements'!$M$5:$M$70,'M1 Requirements'!$H$5:$H$70,"*"&A15&"*"))) -> not selected
A16: DC-12 | B16: L1 Presentation | C16: Store search (postcode / location) | D16: UI | E16: Find store by postcode or optional location | F16: Block app if location denied | G16: =COUNTIF('M1 Requirements'!$H$5:$H$70,"*"&A16&"*") -> 2 | H16: =IF(_xlfn.MINIFS('M1 Requirements'!$M$5:$M$70,'M1 Requirements'!$H$5:$H$70,"*"&A16&"*")=0,"not selected",INDEX({"R1","R2","R3","Beyond"},_xlfn.MINIFS('M1 Requirements'!$M$5:$M$70,'M1 Requirements'!$H$5:$H$70,"*"&A16&"*"))) -> not selected
... A45: DC-41 | B45: Cross-cutting | C45: Template & safety review process | D45: Process | E45: Human review/approval of templates and RB tests | F45: Release unreviewed mounting guidance | G45: =COUNTIF('M1 Requirements'!$H$5:$H$70,"*"&A45&"*") -> 2 | H45: =IF(_xlfn.MINIFS('M1 Requirements'!$M$5:$M$70,'M1 Requirements'!$H$5:$H$70,"*"&A45&"*")=0,"not selected",INDEX({"R1","R2","R3","Beyond"},_xlfn.MINIFS('M1 Requirements'!$M$5:$M$70,'M1 Requirements'!$H$5:$H$70,"*"&A45&"*"))) -> not selected
B47: Layers
B48: L1 Presentation | C48: Mobile web UI the customer sees
B49: L2 Application | C49: Orchestration, project state, persistence
B50: L3 AI (proposes) | C50: LLM agents: classify, extract, phrase, propose – never decide
B51: L4 Control (decides) | C51: Deterministic code: gates G0–G4, rule engine – decides safety, products, quantities
B52: L5 Data | C52: Catalogue, store map, templates, manufacturer data, evidence log
B53: Cross-cutting | C53: Language, security/privacy, monitoring, accessibility, integration, review process

Sheet M1 Traceability
A1: Method 1 – Traceability matrix (requirement × design component)
A2: ● = component implements or supports the requirement
C3: L1 | D3: L1 | E3: L1 | F3: L1 | G3: L1 | H3: L1 | I3: L1 | J3: L1 | K3: L1 | L3: L1 | M3: L1 | N3: L1 | O3: L2 | P3: L2 | Q3: L2 | R3: L2 | S3: L3 | T3: L3 | U3: L3 | V3: L3 | W3: L3 | X3: L4 | Y3: L4 | Z3: L4 | AA3: L4 | AB3: L4 | AC3: L4 | AD3: L4 | AE3: L4 | AF3: L5 | AG3: L5 | AH3: L5 | AI3: L5 | AJ3: L5 | AK3: L5 | AL3: Cross-cutting | AM3: Cross-cutting | AN3: Cross-cutting | AO3: Cross-cutting | AP3: Cross-cutting | AQ3: Cross-cutting
A4: ID | B4: Type | C4: DC-01 | D4: DC-02 | E4: DC-03 | F4: DC-04 | G4: DC-05 | H4: DC-06 | I4: DC-07 | J4: DC-08 | K4: DC-09 | L4: DC-10 | M4: DC-11 | N4: DC-12 | O4: DC-13 | P4: DC-14 | Q4: DC-15 | R4: DC-16 | S4: DC-17 | T4: DC-18 | U4: DC-19 | V4: DC-20 | W4: DC-21 | X4: DC-22 | Y4: DC-23 | Z4: DC-24 | AA4: DC-25 | AB4: DC-26 | AC4: DC-27 | AD4: DC-28 | AE4: DC-29 | AF4: DC-30 | AG4: DC-31 | AH4: DC-32 | AI4: DC-33 | AJ4: DC-34 | AK4: DC-35 | AL4: DC-36 | AM4: DC-37 | AN4: DC-38 | AO4: DC-39 | AP4: DC-40 | AQ4: DC-41
A5: FR-01 | B5: Functional | O5: ● | P5: ● | Q5: ●
A6: FR-02 | B6: Functional | C6: ● | K6: ● | S6: ● | W6: ●
A7: FR-03 | B7: Functional | D7: ● | S7: ● | W7: ●
A8: FR-04 | B8: Functional | D8: ● | Y8: ● | AE8: ●
A9: FR-05 | B9: Functional | E9: ● | T9: ● | Y9: ● | AH9: ●
A10: FR-06 | B10: Functional | F10: ● | U10: ● | Z10: ● | AH10: ●
A11: FR-07 | B11: Functional | D11: ● | AE11: ●
A12: FR-08 | B12: Functional | Z12: ● | AA12: ● | AF12: ●
A13: FR-09 | B13: Functional | Z13: ● | AI13: ● | AJ13: ●
A14: FR-10 | B14: Functional | F14: ● | V14: ● | AJ14: ●
A15: FR-11 | B15: Functional | F15: ● | AG15: ● | AK15: ●
A16: FR-12 | B16: Functional | F16: ● | Z16: ● | AD16: ●
A17: FR-13 | B17: Functional | N17: ● | AP17: ●
A18: FR-14 | B18: Functional | H18: ● | Q18: ●
A19: FR-15 | B19: Functional | G19: ● | P19: ● | X19: ●
A20: FR-16 | B20: Functional | J20: ● | AH20: ● | AI20: ●
A21: FR-17 | B21: Functional | I21: ●
A22: FR-18 | B22: Functional | F22: ● | AG22: ● | AK22: ●
A23: FR-19 | B23: Functional | M23: ● | R23: ● | Z23: ●
A24: FR-20 | B24: Functional | J24: ● | P24: ● | R24: ●
A25: FR-21 | B25: Functional | AP25: ●
A26: FR-22 | B26: Functional | I26: ● | AP26: ●
A27: FR-23 | B27: Functional | Z27: ● | AD27: ● | AP27: ●
A28: FR-24 | B28: Functional | L28: ● | S28: ●
A29: SR-01 | B29: Safety | D29: ● | P29: ● | Y29: ●
A30: SR-02 | B30: Safety | W30: ● | Y30: ● | Z30: ●
A31: SR-03 | B31: Safety | Y31: ● | Z31: ● | AH31: ●
A32: SR-04 | B32: Safety | Z32: ● | AI32: ●
A33: SR-05 | B33: Safety | G33: ● | Z33: ●
A34: SR-06 | B34: Safety | G34: ● | P34: ● | Y34: ●
A35: SR-07 | B35: Safety | F35: ● | Z35: ● | AI35: ●
A36: SR-08 | B36: Safety | P36: ● | R36: ● | Z36: ●
A37: SR-09 | B37: Safety | G37: ● | X37: ●
A38: SR-10 | B38: Safety | AH38: ● | AQ38: ●
A39: NFR-01 | B39: Non-functional | C39: ● | F39: ● | AO39: ●
A40: NFR-02 | B40: Non-functional | O40: ● | Z40: ● | AF40: ●
...

Sheet M2 Proposal
A1: Method 2 – Proposed release & MoSCoW per requirement
A2: Proposal by Claude for team review · change via 'Team decision' column
A4: ID | B4: Type | C4: Category | D4: Requirement | E4: Proposed release | F4: MoSCoW (in that release) | G4: Rationale | H4: Design components (for the part in the proposed release) | I4: Release no. | J4: Team decision | K4: Team comment
A5: FR-01 | B5: Functional | C5: Project lifecycle | D5: Create, save, resume and delete a project | E5: R1 | F5: Should | G5: Session-only save is enough for the demo; full persistence in R2 | H5: DC-13, DC-14, DC-15 | I5: =IFERROR(MATCH(E5,{"R1","R2","R3","Beyond"},0),"") -> 1
A6: FR-02 | B6: Functional | C6: Project entry | D6: Accept a free-text project description and multiple role-labelled photos | E6: R1 | F6: Must | G6: R1 = free text only (core of UC-1). Photo part moves to R3 (adds most safety/privacy work) | H6: DC-01, DC-17 | I6: =IFERROR(MATCH(E6,{"R1","R2","R3","Beyond"},0),"") -> 1
A7: FR-03 | B7: Functional | C7: Project entry | D7: Classify project intent and extract candidate objects/visible labels | E7: R1 | F7: Must | G7: Intent classification from text is the entry to the flow. Photo object extraction in R3 | H7: DC-17, DC-02 | I7: =IFERROR(MATCH(E7,{"R1","R2","R3","Beyond"},0),"") -> 1
A8: FR-04 | B8: Functional | C8: Clarification & facts | D8: Capture measurements, units, constraints and owned items | E8: R1 | F8: Must | G8: Confirmed load and wall type are safety-critical. Owned-item part covered by FR-07 (R2) | H8: DC-02, DC-23 | I8: =IFERROR(MATCH(E8,{"R1","R2","R3","Beyond"},0),"") -> 1
A9: FR-05 | B9: Functional | C9: Clarification & facts | D9: Ask dependency-aware follow-up questions | E9: R1 | F9: Must | G9: Questions are how missing safety facts are collected | H9: DC-03, DC-18, DC-23, DC-32 | I9: =IFERROR(MATCH(E9,{"R1","R2","R3","Beyond"},0),"") -> 1
A10: FR-06 | B10: Functional | C10: Planning | D10: Generate a structured bill of materials (BOM) | E10: R1 | F10: Must | G10: The shopping list is the core product value | H10: DC-19, DC-24, DC-32, DC-04 | I10: =IFERROR(MATCH(E10,{"R1","R2","R3","Beyond"},0),"") -> 1
A11: FR-07 | B11: Functional | C11: Planning | D11: Reconcile suitable owned items against the BOM | E11: R2 | F11: Should | G11: Valuable (problem P2) but not needed for a safe first flow | H11: DC-29, DC-02 | I11: =IFERROR(MATCH(E11,{"R1","R2","R3","Beyond"},0),"") -> 2
A12: FR-08 | B12: Functional | C12: Validation | D12: Match exact catalogue products and variants | E12: R1 | F12: Must | G12: Zero hallucinated products is a KPI | H12: DC-25, DC-24, DC-30 | I12: =IFERROR(MATCH(E12,{"R1","R2","R3","Beyond"},0),"") -> 1
A13: FR-09 | B13: Functional | C13: Validation | D13: Validate product and component compatibility | E13: R1 | F13: Must | G13: Compatibility is the main differentiator (problem P1) | H13: DC-24, DC-33, DC-34 | I13: =IFERROR(MATCH(E13,{"R1","R2","R3","Beyond"},0),"") -> 1
A14: FR-10 | B14: Functional | C14: Validation | D14: Explain recommendations and unresolved facts | E14: R2 | F14: Must | G14: R1 shows the quantity basis/rule ID; full explanations in R2 | H14: DC-20, DC-04, DC-34 | I14: =IFERROR(MATCH(E14,{"R1","R2","R3","Beyond"},0),"") -> 2
A15: FR-11 | B15: Functional | C15: Shopping | D15: Show price, availability and store information | E15: R1 | F15: Must | G15: Price, stock, aisle with mock labels - needed for the in-store use case | H15: DC-04, DC-31, DC-35 | I15: =IFERROR(MATCH(E15,{"R1","R2","R3","Beyond"},0),"") -> 1
A16: FR-12 | B16: Functional | C16: Shopping | D16: Offer feasible basket options and alternatives | E16: R2 | F16: Should | G16: Needs the core rule engine first | H16: DC-28, DC-24, DC-04 | I16: =IFERROR(MATCH(E16,{"R1","R2","R3","Beyond"},0),"") -> 2
... A70: RB-14 | B70: Release-blocking test | C70: Revalidation | D70: A changed product during shopping triggers revalidation of affected assembly steps. | E70: R3 | F70: Must | G70: Scanner arrives in R3 | H70: DC-11, DC-16 | I70: =IFERROR(MATCH(E70,{"R1","R2","R3","Beyond"},0),"") -> 3

Sheet M2 Components by Release
A1: Method 2 – Which design components are built in which release
A2: Calculated from M2 Proposal · 'First needed in' = earliest release of any linked requirement
A4: ID | B4: Layer | C4: Component | D4: Type | E4: First needed in | F4: # reqs R1 | G4: # reqs R2 | H4: # reqs R3 | I4: # reqs Beyond | J4: What is built when
A5: DC-01 | B5: L1 Presentation | C5: Project entry screen (text + template picker) | D5: UI | E5: =IF(_xlfn.MINIFS('M2 Proposal'!$I$5:$I$70,'M2 Proposal'!$H$5:$H$70,"*"&A5&"*")=0,"–",INDEX({"R1","R2","R3","Beyond"},_xlfn.MINIFS('M2 Proposal'!$I$5:$I$70,'M2 Proposal'!$H$5:$H$70,"*"&A5&"*"))) -> R1 | F5: =COUNTIFS('M2 Proposal'!$H$5:$H$70,"*"&A5&"*",'M2 Proposal'!$E$5:$E$70,"R1") -> 2 | G5: =COUNTIFS('M2 Proposal'!$H$5:$H$70,"*"&A5&"*",'M2 Proposal'!$E$5:$E$70,"R2") -> 0 | H5: =COUNTIFS('M2 Proposal'!$H$5:$H$70,"*"&A5&"*",'M2 Proposal'!$E$5:$E$70,"R3") -> 0 | I5: =COUNTIFS('M2 Proposal'!$H$5:$H$70,"*"&A5&"*",'M2 Proposal'!$E$5:$E$70,"Beyond") -> 0 | J5: R1 text + 2 templates · R2 5-10 templates
A6: DC-02 | B6: L1 Presentation | C6: Project summary & fact confirmation | D6: UI | E6: =IF(_xlfn.MINIFS('M2 Proposal'!$I$5:$I$70,'M2 Proposal'!$H$5:$H$70,"*"&A6&"*")=0,"–",INDEX({"R1","R2","R3","Beyond"},_xlfn.MINIFS('M2 Proposal'!$I$5:$I$70,'M2 Proposal'!$H$5:$H$70,"*"&A6&"*"))) -> R1 | F6: =COUNTIFS('M2 Proposal'!$H$5:$H$70,"*"&A6&"*",'M2 Proposal'!$E$5:$E$70,"R1") -> 4 | G6: =COUNTIFS('M2 Proposal'!$H$5:$H$70,"*"&A6&"*",'M2 Proposal'!$E$5:$E$70,"R2") -> 1 | H6: =COUNTIFS('M2 Proposal'!$H$5:$H$70,"*"&A6&"*",'M2 Proposal'!$E$5:$E$70,"R3") -> 0 | I6: =COUNTIFS('M2 Proposal'!$H$5:$H$70,"*"&A6&"*",'M2 Proposal'!$E$5:$E$70,"Beyond") -> 0 | J6: R1 load/wall type confirm · R2 owned items · R3 photo facts
A7: DC-03 | B7: L1 Presentation | C7: Clarification question UI | D7: UI | E7: =IF(_xlfn.MINIFS('M2 Proposal'!$I$5:$I$70,'M2 Proposal'!$H$5:$H$70,"*"&A7&"*")=0,"–",INDEX({"R1","R2","R3","Beyond"},_xlfn.MINIFS('M2 Proposal'!$I$5:$I$70,'M2 Proposal'!$H$5:$H$70,"*"&A7&"*"))) -> R1 | F7: =COUNTIFS('M2 Proposal'!$H$5:$H$70,"*"&A7&"*",'M2 Proposal'!$E$5:$E$70,"R1") -> 1 | G7: =COUNTIFS('M2 Proposal'!$H$5:$H$70,"*"&A7&"*",'M2 Proposal'!$E$5:$E$70,"R2") -> 0 | H7: =COUNTIFS('M2 Proposal'!$H$5:$H$70,"*"&A7&"*",'M2 Proposal'!$E$5:$E$70,"R3") -> 0 | I7: =COUNTIFS('M2 Proposal'!$H$5:$H$70,"*"&A7&"*",'M2 Proposal'!$E$5:$E$70,"Beyond") -> 0
A8: DC-04 | B8: L1 Presentation | C8: BOM / shopping list view | D8: UI | E8: =IF(_xlfn.MINIFS('M2 Proposal'!$I$5:$I$70,'M2 Proposal'!$H$5:$H$70,"*"&A8&"*")=0,"–",INDEX({"R1","R2","R3","Beyond"},_xlfn.MINIFS('M2 Proposal'!$I$5:$I$70,'M2 Proposal'!$H$5:$H$70,"*"&A8&"*"))) -> R1 | F8: =COUNTIFS('M2 Proposal'!$H$5:$H$70,"*"&A8&"*",'M2 Proposal'!$E$5:$E$70,"R1") -> 6 | G8: =COUNTIFS('M2 Proposal'!$H$5:$H$70,"*"&A8&"*",'M2 Proposal'!$E$5:$E$70,"R2") -> 3 | H8: =COUNTIFS('M2 Proposal'!$H$5:$H$70,"*"&A8&"*",'M2 Proposal'!$E$5:$E$70,"R3") -> 1 | I8: =COUNTIFS('M2 Proposal'!$H$5:$H$70,"*"&A8&"*",'M2 Proposal'!$E$5:$E$70,"Beyond") -> 0 | J8: R1 list with mock labels · R2 explanations, alternatives · R3 verified aisles
A9: DC-05 | B9: L1 Presentation | C9: Safety banner & hand-off UI | D9: UI | E9: =IF(_xlfn.MINIFS('M2 Proposal'!$I$5:$I$70,'M2 Proposal'!$H$5:$H$70,"*"&A9&"*")=0,"–",INDEX({"R1","R2","R3","Beyond"},_xlfn.MINIFS('M2 Proposal'!$I$5:$I$70,'M2 Proposal'!$H$5:$H$70,"*"&A9&"*"))) -> R1 | F9: =COUNTIFS('M2 Proposal'!$H$5:$H$70,"*"&A9&"*",'M2 Proposal'!$E$5:$E$70,"R1") -> 5 | G9: =COUNTIFS('M2 Proposal'!$H$5:$H$70,"*"&A9&"*",'M2 Proposal'!$E$5:$E$70,"R2") -> 0 | H9: =COUNTIFS('M2 Proposal'!$H$5:$H$70,"*"&A9&"*",'M2 Proposal'!$E$5:$E$70,"R3") -> 0 | I9: =COUNTIFS('M2 Proposal'!$H$5:$H$70,"*"&A9&"*",'M2 Proposal'!$E$5:$E$70,"Beyond") -> 0
A10: DC-06 | B10: L1 Presentation | C10: Checklist & offline cache (PWA) | D10: UI | E10: =IF(_xlfn.MINIFS('M2 Proposal'!$I$5:$I$70,'M2 Proposal'!$H$5:$H$70,"*"&A10&"*")=0,"–",INDEX({"R1","R2","R3","Beyond"},_xlfn.MINIFS('M2 Proposal'!$I$5:$I$70,'M2 Proposal'!$H$5:$H$70,"*"&A10&"*"))) -> R2 | F10: =COUNTIFS('M2 Proposal'!$H$5:$H$70,"*"&A10&"*",'M2 Proposal'!$E$5:$E$70,"R1") -> 0 | G10: =COUNTIFS('M2 Proposal'!$H$5:$H$70,"*"&A10&"*",'M2 Proposal'!$E$5:$E$70,"R2") -> 2 | H10: =COUNTIFS('M2 Proposal'!$H$5:$H$70,"*"&A10&"*",'M2 Proposal'!$E$5:$E$70,"R3") -> 0 | I10: =COUNTIFS('M2 Proposal'!$H$5:$H$70,"*"&A10&"*",'M2 Proposal'!$E$5:$E$70,"Beyond") -> 0
A11: DC-07 | B11: L1 Presentation | C11: Export / share module | D11: UI | E11: =IF(_xlfn.MINIFS('M2 Proposal'!$I$5:$I$70,'M2 Proposal'!$H$5:$H$70,"*"&A11&"*")=0,"–",INDEX({"R1","R2","R3","Beyond"},_xlfn.MINIFS('M2 Proposal'!$I$5:$I$70,'M2 Proposal'!$H$5:$H$70,"*"&A11&"*"))) -> R2 | F11: =COUNTIFS('M2 Proposal'!$H$5:$H$70,"*"&A11&"*",'M2 Proposal'!$E$5:$E$70,"R1") -> 0 | G11: =COUNTIFS('M2 Proposal'!$H$5:$H$70,"*"&A11&"*",'M2 Proposal'!$E$5:$E$70,"R2") -> 2 | H11: =COUNTIFS('M2 Proposal'!$H$5:$H$70,"*"&A11&"*",'M2 Proposal'!$E$5:$E$70,"R3") -> 1 | I11: =COUNTIFS('M2 Proposal'!$H$5:$H$70,"*"&A11&"*",'M2 Proposal'!$E$5:$E$70,"Beyond") -> 0
A12: DC-08 | B12: L1 Presentation | C12: Assembly guide view | D12: UI | E12: =IF(_xlfn.MINIFS('M2 Proposal'!$I$5:$I$70,'M2 Proposal'!$H$5:$H$70,"*"&A12&"*")=0,"–",INDEX({"R1","R2","R3","Beyond"},_xlfn.MINIFS('M2 Proposal'!$I$5:$I$70,'M2 Proposal'!$H$5:$H$70,"*"&A12&"*"))) -> R2 | F12: =COUNTIFS('M2 Proposal'!$H$5:$H$70,"*"&A12&"*",'M2 Proposal'!$E$5:$E$70,"R1") -> 0 | G12: =COUNTIFS('M2 Proposal'!$H$5:$H$70,"*"&A12&"*",'M2 Proposal'!$E$5:$E$70,"R2") -> 1 | H12: =COUNTIFS('M2 Proposal'!$H$5:$H$70,"*"&A12&"*",'M2 Proposal'!$E$5:$E$70,"R3") -> 1 | I12: =COUNTIFS('M2 Proposal'!$H$5:$H$70,"*"&A12&"*",'M2 Proposal'!$E$5:$E$70,"Beyond") -> 0
A13: DC-09 | B13: L1 Presentation | C13: Photo capture & role labelling | D13: UI | E13: =IF(_xlfn.MINIFS('M2 Proposal'!$I$5:$I$70,'M2 Proposal'!$H$5:$H$70,"*"&A13&"*")=0,"–",INDEX({"R1","R2","R3","Beyond"},_xlfn.MINIFS('M2 Proposal'!$I$5:$I$70,'M2 Proposal'!$H$5:$H$70,"*"&A13&"*"))) -> R3 | F13: =COUNTIFS('M2 Proposal'!$H$5:$H$70,"*"&A13&"*",'M2 Proposal'!$E$5:$E$70,"R1") -> 0 | G13: =COUNTIFS('M2 Proposal'!$H$5:$H$70,"*"&A13&"*",'M2 Proposal'!$E$5:$E$70,"R2") -> 0 | H13: =COUNTIFS('M2 Proposal'!$H$5:$H$70,"*"&A13&"*",'M2 Proposal'!$E$5:$E$70,"R3") -> 1 | I13: =COUNTIFS('M2 Proposal'!$H$5:$H$70,"*"&A13&"*",'M2 Proposal'!$E$5:$E$70,"Beyond") -> 0
A14: DC-10 | B14: L1 Presentation | C14: Voice input (speech-to-text) | D14: UI | E14: =IF(_xlfn.MINIFS('M2 Proposal'!$I$5:$I$70,'M2 Proposal'!$H$5:$H$70,"*"&A14&"*")=0,"–",INDEX({"R1","R2","R3","Beyond"},_xlfn.MINIFS('M2 Proposal'!$I$5:$I$70,'M2 Proposal'!$H$5:$H$70,"*"&A14&"*"))) -> R3 | F14: =COUNTIFS('M2 Proposal'!$H$5:$H$70,"*"&A14&"*",'M2 Proposal'!$E$5:$E$70,"R1") -> 0 | G14: =COUNTIFS('M2 Proposal'!$H$5:$H$70,"*"&A14&"*",'M2 Proposal'!$E$5:$E$70,"R2") -> 0 | H14: =COUNTIFS('M2 Proposal'!$H$5:$H$70,"*"&A14&"*",'M2 Proposal'!$E$5:$E$70,"R3") -> 1 | I14: =COUNTIFS('M2 Proposal'!$H$5:$H$70,"*"&A14&"*",'M2 Proposal'!$E$5:$E$70,"Beyond") -> 0
A15: DC-11 | B15: L1 Presentation | C15: Barcode / product scanner | D15: UI | E15: =IF(_xlfn.MINIFS('M2 Proposal'!$I$5:$I$70,'M2 Proposal'!$H$5:$H$70,"*"&A15&"*")=0,"–",INDEX({"R1","R2","R3","Beyond"},_xlfn.MINIFS('M2 Proposal'!$I$5:$I$70,'M2 Proposal'!$H$5:$H$70,"*"&A15&"*"))) -> R3 | F15: =COUNTIFS('M2 Proposal'!$H$5:$H$70,"*"&A15&"*",'M2 Proposal'!$E$5:$E$70,"R1") -> 0 | G15: =COUNTIFS('M2 Proposal'!$H$5:$H$70,"*"&A15&"*",'M2 Proposal'!$E$5:$E$70,"R2") -> 0 | H15: =COUNTIFS('M2 Proposal'!$H$5:$H$70,"*"&A15&"*",'M2 Proposal'!$E$5:$E$70,"R3") -> 2 | I15: =COUNTIFS('M2 Proposal'!$H$5:$H$70,"*"&A15&"*",'M2 Proposal'!$E$5:$E$70,"Beyond") -> 0
A16: DC-12 | B16: L1 Presentation | C16: Store search (postcode / location) | D16: UI | E16: =IF(_xlfn.MINIFS('M2 Proposal'!$I$5:$I$70,'M2 Proposal'!$H$5:$H$70,"*"&A16&"*")=0,"–",INDEX({"R1","R2","R3","Beyond"},_xlfn.MINIFS('M2 Proposal'!$I$5:$I$70,'M2 Proposal'!$H$5:$H$70,"*"&A16&"*"))) -> R3 | F16: =COUNTIFS('M2 Proposal'!$H$5:$H$70,"*"&A16&"*",'M2 Proposal'!$E$5:$E$70,"R1") -> 0 | G16: =COUNTIFS('M2 Proposal'!$H$5:$H$70,"*"&A16&"*",'M2 Proposal'!$E$5:$E$70,"R2") -> 0 | H16: =COUNTIFS('M2 Proposal'!$H$5:$H$70,"*"&A16&"*",'M2 Proposal'!$E$5:$E$70,"R3") -> 2 | I16: =COUNTIFS('M2 Proposal'!$H$5:$H$70,"*"&A16&"*",'M2 Proposal'!$E$5:$E$70,"Beyond") -> 0
A17: DC-13 | B17: L2 Application | C17: Orchestrator / flow controller | D17: Code | E17: =IF(_xlfn.MINIFS('M2 Proposal'!$I$5:$I$70,'M2 Proposal'!$H$5:$H$70,"*"&A17&"*")=0,"–",INDEX({"R1","R2","R3","Beyond"},_xlfn.MINIFS('M2 Proposal'!$I$5:$I$70,'M2 Proposal'!$H$5:$H$70,"*"&A17&"*"))) -> R1 | F17: =COUNTIFS('M2 Proposal'!$H$5:$H$70,"*"&A17&"*",'M2 Proposal'!$E$5:$E$70,"R1") -> 3 | G17: =COUNTIFS('M2 Proposal'!$H$5:$H$70,"*"&A17&"*",'M2 Proposal'!$E$5:$E$70,"R2") -> 0 | H17: =COUNTIFS('M2 Proposal'!$H$5:$H$70,"*"&A17&"*",'M2 Proposal'!$E$5:$E$70,"R3") -> 0 | I17: =COUNTIFS('M2 Proposal'!$H$5:$H$70,"*"&A17&"*",'M2 Proposal'!$E$5:$E$70,"Beyond") -> 0 | J17: R1 fixed pipeline G0→G4 · R3 backend hardening
A18: DC-14 | B18: L2 Application | C18: Project state machine | D18: Code | E18: =IF(_xlfn.MINIFS('M2 Proposal'!$I$5:$I$70,'M2 Proposal'!$H$5:$H$70,"*"&A18&"*")=0,"–",INDEX({"R1","R2","R3","Beyond"},_xlfn.MINIFS('M2 Proposal'!$I$5:$I$70,'M2 Proposal'!$H$5:$H$70,"*"&A18&"*"))) -> R1 | F18: =COUNTIFS('M2 Proposal'!$H$5:$H$70,"*"&A18&"*",'M2 Proposal'!$E$5:$E$70,"R1") -> 6 | G18: =COUNTIFS('M2 Proposal'!$H$5:$H$70,"*"&A18&"*",'M2 Proposal'!$E$5:$E$70,"R2") -> 0 | H18: =COUNTIFS('M2 Proposal'!$H$5:$H$70,"*"&A18&"*",'M2 Proposal'!$E$5:$E$70,"R3") -> 1 | I18: =COUNTIFS('M2 Proposal'!$H$5:$H$70,"*"&A18&"*",'M2 Proposal'!$E$5:$E$70,"Beyond") -> 0
A19: DC-15 | B19: L2 Application | C19: Project persistence | D19: Code | E19: =IF(_xlfn.MINIFS('M2 Proposal'!$I$5:$I$70,'M2 Proposal'!$H$5:$H$70,"*"&A19&"*")=0,"–",INDEX({"R1","R2","R3","Beyond"},_xlfn.MINIFS('M2 Proposal'!$I$5:$I$70,'M2 Proposal'!$H$5:$H$70,"*"&A19&"*"))) -> R1 | F19: =COUNTIFS('M2 Proposal'!$H$5:$H$70,"*"&A19&"*",'M2 Proposal'!$E$5:$E$70,"R1") -> 1 | G19: =COUNTIFS('M2 Proposal'!$H$5:$H$70,"*"&A19&"*",'M2 Proposal'!$E$5:$E$70,"R2") -> 1 | H19: =COUNTIFS('M2 Proposal'!$H$5:$H$70,"*"&A19&"*",'M2 Proposal'!$E$5:$E$70,"R3") -> 0 | I19: =COUNTIFS('M2 Proposal'!$H$5:$H$70,"*"&A19&"*",'M2 Proposal'!$E$5:$E$70,"Beyond") -> 0 | J19: R1 session only · R2 local save · R3 backend
A20: DC-16 | B20: L2 Application | C20: Revalidation trigger | D20: Code | E20: =IF(_xlfn.MINIFS('M2 Proposal'!$I$5:$I$70,'M2 Proposal'!$H$5:$H$70,"*"&A20&"*")=0,"–",INDEX({"R1","R2","R3","Beyond"},_xlfn.MINIFS('M2 Proposal'!$I$5:$I$70,'M2 Proposal'!$H$5:$H$70,"*"&A20&"*"))) -> R1 | F20: =COUNTIFS('M2 Proposal'!$H$5:$H$70,"*"&A20&"*",'M2 Proposal'!$E$5:$E$70,"R1") -> 2 | G20: =COUNTIFS('M2 Proposal'!$H$5:$H$70,"*"&A20&"*",'M2 Proposal'!$E$5:$E$70,"R2") -> 0 | H20: =COUNTIFS('M2 Proposal'!$H$5:$H$70,"*"&A20&"*",'M2 Proposal'!$E$5:$E$70,"R3") -> 3 | I20: =COUNTIFS('M2 Proposal'!$H$5:$H$70,"*"&A20&"*",'M2 Proposal'!$E$5:$E$70,"Beyond") -> 0
A21: DC-17 | B21: L3 AI (proposes) | C21: Intake agent | D21: AI | E21: =IF(_xlfn.MINIFS('M2 Proposal'!$I$5:$I$70,'M2 Proposal'!$H$5:$H$70,"*"&A21&"*")=0,"–",INDEX({"R1","R2","R3","Beyond"},_xlfn.MINIFS('M2 Proposal'!$I$5:$I$70,'M2 Proposal'!$H$5:$H$70,"*"&A21&"*"))) -> R1 | F21: =COUNTIFS('M2 Proposal'!$H$5:$H$70,"*"&A21&"*",'M2 Proposal'!$E$5:$E$70,"R1") -> 5 | G21: =COUNTIFS('M2 Proposal'!$H$5:$H$70,"*"&A21&"*",'M2 Proposal'!$E$5:$E$70,"R2") -> 0 | H21: =COUNTIFS('M2 Proposal'!$H$5:$H$70,"*"&A21&"*",'M2 Proposal'!$E$5:$E$70,"R3") -> 1 | I21: =COUNTIFS('M2 Proposal'!$H$5:$H$70,"*"&A21&"*",'M2 Proposal'!$E$5:$E$70,"Beyond") -> 0 | J21: R1 text intake · R3 photo/voice input
A22: DC-18 | B22: L3 AI (proposes) | C22: Clarification agent | D22: AI | E22: =IF(_xlfn.MINIFS('M2 Proposal'!$I$5:$I$70,'M2 Proposal'!$H$5:$H$70,"*"&A22&"*")=0,"–",INDEX({"R1","R2","R3","Beyond"},_xlfn.MINIFS('M2 Proposal'!$I$5:$I$70,'M2 Proposal'!$H$5:$H$70,"*"&A22&"*"))) -> R1 | F22: =COUNTIFS('M2 Proposal'!$H$5:$H$70,"*"&A22&"*",'M2 Proposal'!$E$5:$E$70,"R1") -> 2 | G22: =COUNTIFS('M2 Proposal'!$H$5:$H$70,"*"&A22&"*",'M2 Proposal'!$E$5:$E$70,"R2") -> 0 | H22: =COUNTIFS('M2 Proposal'!$H$5:$H$70,"*"&A22&"*",'M2 Proposal'!$E$5:$E$70,"R3") -> 0 | I22: =COUNTIFS('M2 Proposal'!$H$5:$H$70,"*"&A22&"*",'M2 Proposal'!$E$5:$E$70,"Beyond") -> 0
A23: DC-19 | B23: L3 AI (proposes) | C23: Planner agent | D23: AI | E23: =IF(_xlfn.MINIFS('M2 Proposal'!$I$5:$I$70,'M2 Proposal'!$H$5:$H$70,"*"&A23&"*")=0,"–",INDEX({"R1","R2","R3","Beyond"},_xlfn.MINIFS('M2 Proposal'!$I$5:$I$70,'M2 Proposal'!$H$5:$H$70,"*"&A23&"*"))) -> R1 | F23: =COUNTIFS('M2 Proposal'!$H$5:$H$70,"*"&A23&"*",'M2 Proposal'!$E$5:$E$70,"R1") -> 1 | G23: =COUNTIFS('M2 Proposal'!$H$5:$H$70,"*"&A23&"*",'M2 Proposal'!$E$5:$E$70,"R2") -> 0 | H23: =COUNTIFS('M2 Proposal'!$H$5:$H$70,"*"&A23&"*",'M2 Proposal'!$E$5:$E$70,"R3") -> 0 | I23: =COUNTIFS('M2 Proposal'!$H$5:$H$70,"*"&A23&"*",'M2 Proposal'!$E$5:$E$70,"Beyond") -> 0
A24: DC-20 | B24: L3 AI (proposes) | C24: Explanation generator | D24: AI | E24: =IF(_xlfn.MINIFS('M2 Proposal'!$I$5:$I$70,'M2 Proposal'!$H$5:$H$70,"*"&A24&"*")=0,"–",INDEX({"R1","R2","R3","Beyond"},_xlfn.MINIFS('M2 Proposal'!$I$5:$I$70,'M2 Proposal'!$H$5:$H$70,"*"&A24&"*"))) -> R2 | F24: =COUNTIFS('M2 Proposal'!$H$5:$H$70,"*"&A24&"*",'M2 Proposal'!$E$5:$E$70,"R1") -> 0 | G24: =COUNTIFS('M2 Proposal'!$H$5:$H$70,"*"&A24&"*",'M2 Proposal'!$E$5:$E$70,"R2") -> 1 | H24: =COUNTIFS('M2 Proposal'!$H$5:$H$70,"*"&A24&"*",'M2 Proposal'!$E$5:$E$70,"R3") -> 0 | I24: =COUNTIFS('M2 Proposal'!$H$5:$H$70,"*"&A24&"*",'M2 Proposal'!$E$5:$E$70,"Beyond") -> 0
A25: DC-21 | B25: L3 AI (proposes) | C25: Vision extraction agent | D25: AI | E25: =IF(_xlfn.MINIFS('M2 Proposal'!$I$5:$I$70,'M2 Proposal'!$H$5:$H$70,"*"&A25&"*")=0,"–",INDEX({"R1","R2","R3","Beyond"},_xlfn.MINIFS('M2 Proposal'!$I$5:$I$70,'M2 Proposal'!$H$5:$H$70,"*"&A25&"*"))) -> R3 | F25: =COUNTIFS('M2 Proposal'!$H$5:$H$70,"*"&A25&"*",'M2 Proposal'!$E$5:$E$70,"R1") -> 0 | G25: =COUNTIFS('M2 Proposal'!$H$5:$H$70,"*"&A25&"*",'M2 Proposal'!$E$5:$E$70,"R2") -> 0 | H25: =COUNTIFS('M2 Proposal'!$H$5:$H$70,"*"&A25&"*",'M2 Proposal'!$E$5:$E$70,"R3") -> 1 | I25: =COUNTIFS('M2 Proposal'!$H$5:$H$70,"*"&A25&"*",'M2 Proposal'!$E$5:$E$70,"Beyond") -> 0
A26: DC-22 | B26: L4 Control (decides) | C26: G0 Scope / high-risk filter | D26: Code | E26: =IF(_xlfn.MINIFS('M2 Proposal'!$I$5:$I$70,'M2 Proposal'!$H$5:$H$70,"*"&A26&"*")=0,"–",INDEX({"R1","R2","R3","Beyond"},_xlfn.MINIFS('M2 Proposal'!$I$5:$I$70,'M2 Proposal'!$H$5:$H$70,"*"&A26&"*"))) -> R1 | F26: =COUNTIFS('M2 Proposal'!$H$5:$H$70,"*"&A26&"*",'M2 Proposal'!$E$5:$E$70,"R1") -> 2 | G26: =COUNTIFS('M2 Proposal'!$H$5:$H$70,"*"&A26&"*",'M2 Proposal'!$E$5:$E$70,"R2") -> 0 | H26: =COUNTIFS('M2 Proposal'!$H$5:$H$70,"*"&A26&"*",'M2 Proposal'!$E$5:$E$70,"R3") -> 0 | I26: =COUNTIFS('M2 Proposal'!$H$5:$H$70,"*"&A26&"*",'M2 Proposal'!$E$5:$E$70,"Beyond") -> 0
A27: DC-23 | B27: L4 Control (decides) | C27: G1 Required-facts check | D27: Code | E27: =IF(_xlfn.MINIFS('M2 Proposal'!$I$5:$I$70,'M2 Proposal'!$H$5:$H$70,"*"&A27&"*")=0,"–",INDEX({"R1","R2","R3","Beyond"},_xlfn.MINIFS('M2 Proposal'!$I$5:$I$70,'M2 Proposal'!$H$5:$H$70,"*"&A27&"*"))) -> R1 | F27: =COUNTIFS('M2 Proposal'!$H$5:$H$70,"*"&A27&"*",'M2 Proposal'!$E$5:$E$70,"R1") -> 7 | G27: =COUNTIFS('M2 Proposal'!$H$5:$H$70,"*"&A27&"*",'M2 Proposal'!$E$5:$E$70,"R2") -> 0 | H27: =COUNTIFS('M2 Proposal'!$H$5:$H$70,"*"&A27&"*",'M2 Proposal'!$E$5:$E$70,"R3") -> 1 | I27: =COUNTIFS('M2 Proposal'!$H$5:$H$70,"*"&A27&"*",'M2 Proposal'!$E$5:$E$70,"Beyond") -> 0
A28: DC-24 | B28: L4 Control (decides) | C28: Rule engine (R-01...R-16) | D28: Code | E28: =IF(_xlfn.MINIFS('M2 Proposal'!$I$5:$I$70,'M2 Proposal'!$H$5:$H$70,"*"&A28&"*")=0,"–",INDEX({"R1","R2","R3","Beyond"},_xlfn.MINIFS('M2 Proposal'!$I$5:$I$70,'M2 Proposal'!$H$5:$H$70,"*"&A28&"*"))) -> R1 | F28: =COUNTIFS('M2 Proposal'!$H$5:$H$70,"*"&A28&"*",'M2 Proposal'!$E$5:$E$70,"R1") -> 16 | G28: =COUNTIFS('M2 Proposal'!$H$5:$H$70,"*"&A28&"*",'M2 Proposal'!$E$5:$E$70,"R2") -> 1 | H28: =COUNTIFS('M2 Proposal'!$H$5:$H$70,"*"&A28&"*",'M2 Proposal'!$E$5:$E$70,"R3") -> 1 | I28: =COUNTIFS('M2 Proposal'!$H$5:$H$70,"*"&A28&"*",'M2 Proposal'!$E$5:$E$70,"Beyond") -> 1 | J28: R1 rules R-01…R-16 (mock limits) · R2 alternatives, manuals · R3 reviewed limits
A29: DC-25 | B29: L4 Control (decides) | C29: G2 Catalogue check | D29: Code | E29: =IF(_xlfn.MINIFS('M2 Proposal'!$I$5:$I$70,'M2 Proposal'!$H$5:$H$70,"*"&A29&"*")=0,"–",INDEX({"R1","R2","R3","Beyond"},_xlfn.MINIFS('M2 Proposal'!$I$5:$I$70,'M2 Proposal'!$H$5:$H$70,"*"&A29&"*"))) -> R1 | F29: =COUNTIFS('M2 Proposal'!$H$5:$H$70,"*"&A29&"*",'M2 Proposal'!$E$5:$E$70,"R1") -> 2 | G29: =COUNTIFS('M2 Proposal'!$H$5:$H$70,"*"&A29&"*",'M2 Proposal'!$E$5:$E$70,"R2") -> 0 | H29: =COUNTIFS('M2 Proposal'!$H$5:$H$70,"*"&A29&"*",'M2 Proposal'!$E$5:$E$70,"R3") -> 0 | I29: =COUNTIFS('M2 Proposal'!$H$5:$H$70,"*"&A29&"*",'M2 Proposal'!$E$5:$E$70,"Beyond") -> 0
A30: DC-26 | B30: L4 Control (decides) | C30: G4 Output schema validator | D30: Code | E30: =IF(_xlfn.MINIFS('M2 Proposal'!$I$5:$I$70,'M2 Proposal'!$H$5:$H$70,"*"&A30&"*")=0,"–",INDEX({"R1","R2","R3","Beyond"},_xlfn.MINIFS('M2 Proposal'!$I$5:$I$70,'M2 Proposal'!$H$5:$H$70,"*"&A30&"*"))) -> R1 | F30: =COUNTIFS('M2 Proposal'!$H$5:$H$70,"*"&A30&"*",'M2 Proposal'!$E$5:$E$70,"R1") -> 2 | G30: =COUNTIFS('M2 Proposal'!$H$5:$H$70,"*"&A30&"*",'M2 Proposal'!$E$5:$E$70,"R2") -> 0 | H30: =COUNTIFS('M2 Proposal'!$H$5:$H$70,"*"&A30&"*",'M2 Proposal'!$E$5:$E$70,"R3") -> 0 | I30: =COUNTIFS('M2 Proposal'!$H$5:$H$70,"*"&A30&"*",'M2 Proposal'!$E$5:$E$70,"Beyond") -> 0
A31: DC-27 | B31: L4 Control (decides) | C31: Input sanitiser / injection guard | D31: Code | E31: =IF(_xlfn.MINIFS('M2 Proposal'!$I$5:$I$70,'M2 Proposal'!$H$5:$H$70,"*"&A31&"*")=0,"–",INDEX({"R1","R2","R3","Beyond"},_xlfn.MINIFS('M2 Proposal'!$I$5:$I$70,'M2 Proposal'!$H$5:$H$70,"*"&A31&"*"))) -> R1 | F31: =COUNTIFS('M2 Proposal'!$H$5:$H$70,"*"&A31&"*",'M2 Proposal'!$E$5:$E$70,"R1") -> 2 | G31: =COUNTIFS('M2 Proposal'!$H$5:$H$70,"*"&A31&"*",'M2 Proposal'!$E$5:$E$70,"R2") -> 0 | H31: =COUNTIFS('M2 Proposal'!$H$5:$H$70,"*"&A31&"*",'M2 Proposal'!$E$5:$E$70,"R3") -> 0 | I31: =COUNTIFS('M2 Proposal'!$H$5:$H$70,"*"&A31&"*",'M2 Proposal'!$E$5:$E$70,"Beyond") -> 0
A32: DC-28 | B32: L4 Control (decides) | C32: Basket & alternatives calculator | D32: Code | E32: =IF(_xlfn.MINIFS('M2 Proposal'!$I$5:$I$70,'M2 Proposal'!$H$5:$H$70,"*"&A32&"*")=0,"–",INDEX({"R1","R2","R3","Beyond"},_xlfn.MINIFS('M2 Proposal'!$I$5:$I$70,'M2 Proposal'!$H$5:$H$70,"*"&A32&"*"))) -> R1 | F32: =COUNTIFS('M2 Proposal'!$H$5:$H$70,"*"&A32&"*",'M2 Proposal'!$E$5:$E$70,"R1") -> 1 | G32: =COUNTIFS('M2 Proposal'!$H$5:$H$70,"*"&A32&"*",'M2 Proposal'!$E$5:$E$70,"R2") -> 1 | H32: =COUNTIFS('M2 Proposal'!$H$5:$H$70,"*"&A32&"*",'M2 Proposal'!$E$5:$E$70,"R3") -> 0 | I32: =COUNTIFS('M2 Proposal'!$H$5:$H$70,"*"&A32&"*",'M2 Proposal'!$E$5:$E$70,"Beyond") -> 1
A33: DC-29 | B33: L4 Control (decides) | C33: Owned-item reconciler | D33: Code | E33: =IF(_xlfn.MINIFS('M2 Proposal'!$I$5:$I$70,'M2 Proposal'!$H$5:$H$70,"*"&A33&"*")=0,"–",INDEX({"R1","R2","R3","Beyond"},_xlfn.MINIFS('M2 Proposal'!$I$5:$I$70,'M2 Proposal'!$H$5:$H$70,"*"&A33&"*"))) -> R2 | F33: =COUNTIFS('M2 Proposal'!$H$5:$H$70,"*"&A33&"*",'M2 Proposal'!$E$5:$E$70,"R1") -> 0 | G33: =COUNTIFS('M2 Proposal'!$H$5:$H$70,"*"&A33&"*",'M2 Proposal'!$E$5:$E$70,"R2") -> 1 | H33: =COUNTIFS('M2 Proposal'!$H$5:$H$70,"*"&A33&"*",'M2 Proposal'!$E$5:$E$70,"R3") -> 0 | I33: =COUNTIFS('M2 Proposal'!$H$5:$H$70,"*"&A33&"*",'M2 Proposal'!$E$5:$E$70,"Beyond") -> 0
A34: DC-30 | B34: L5 Data | C34: Product catalogue | D34: Data | E34: =IF(_xlfn.MINIFS('M2 Proposal'!$I$5:$I$70,'M2 Proposal'!$H$5:$H$70,"*"&A34&"*")=0,"–",INDEX({"R1","R2","R3","Beyond"},_xlfn.MINIFS('M2 Proposal'!$I$5:$I$70,'M2 Proposal'!$H$5:$H$70,"*"&A34&"*"))) -> R1 | F34: =COUNTIFS('M2 Proposal'!$H$5:$H$70,"*"&A34&"*",'M2 Proposal'!$E$5:$E$70,"R1") -> 4 | G34: =COUNTIFS('M2 Proposal'!$H$5:$H$70,"*"&A34&"*",'M2 Proposal'!$E$5:$E$70,"R2") -> 0 | H34: =COUNTIFS('M2 Proposal'!$H$5:$H$70,"*"&A34&"*",'M2 Proposal'!$E$5:$E$70,"R3") -> 0 | I34: =COUNTIFS('M2 Proposal'!$H$5:$H$70,"*"&A34&"*",'M2 Proposal'!$E$5:$E$70,"Beyond") -> 0
A35: DC-31 | B35: L5 Data | C35: Store map / placement | D35: Data | E35: =IF(_xlfn.MINIFS('M2 Proposal'!$I$5:$I$70,'M2 Proposal'!$H$5:$H$70,"*"&A35&"*")=0,"–",INDEX({"R1","R2","R3","Beyond"},_xlfn.MINIFS('M2 Proposal'!$I$5:$I$70,'M2 Proposal'!$H$5:$H$70,"*"&A35&"*"))) -> R1 | F35: =COUNTIFS('M2 Proposal'!$H$5:$H$70,"*"&A35&"*",'M2 Proposal'!$E$5:$E$70,"R1") -> 4 | G35: =COUNTIFS('M2 Proposal'!$H$5:$H$70,"*"&A35&"*",'M2 Proposal'!$E$5:$E$70,"R2") -> 0 | H35: =COUNTIFS('M2 Proposal'!$H$5:$H$70,"*"&A35&"*",'M2 Proposal'!$E$5:$E$70,"R3") -> 1 | I35: =COUNTIFS('M2 Proposal'!$H$5:$H$70,"*"&A35&"*",'M2 Proposal'!$E$5:$E$70,"Beyond") -> 0
A36: DC-32 | B36: L5 Data | C36: Project templates | D36: Data | E36: =IF(_xlfn.MINIFS('M2 Proposal'!$I$5:$I$70,'M2 Proposal'!$H$5:$H$70,"*"&A36&"*")=0,"–",INDEX({"R1","R2","R3","Beyond"},_xlfn.MINIFS('M2 Proposal'!$I$5:$I$70,'M2 Proposal'!$H$5:$H$70,"*"&A36&"*"))) -> R1 | F36: =COUNTIFS('M2 Proposal'!$H$5:$H$70,"*"&A36&"*",'M2 Proposal'!$E$5:$E$70,"R1") -> 6 | G36: =COUNTIFS('M2 Proposal'!$H$5:$H$70,"*"&A36&"*",'M2 Proposal'!$E$5:$E$70,"R2") -> 1 | H36: =COUNTIFS('M2 Proposal'!$H$5:$H$70,"*"&A36&"*",'M2 Proposal'!$E$5:$E$70,"R3") -> 0 | I36: =COUNTIFS('M2 Proposal'!$H$5:$H$70,"*"&A36&"*",'M2 Proposal'!$E$5:$E$70,"Beyond") -> 0 | J36: R1 2 templates · R2 5-10 templates · R3 expert-reviewed
A37: DC-33 | B37: L5 Data | C37: Manufacturer / system data | D37: Data | E37: =IF(_xlfn.MINIFS('M2 Proposal'!$I$5:$I$70,'M2 Proposal'!$H$5:$H$70,"*"&A37&"*")=0,"–",INDEX({"R1","R2","R3","Beyond"},_xlfn.MINIFS('M2 Proposal'!$I$5:$I$70,'M2 Proposal'!$H$5:$H$70,"*"&A37&"*"))) -> R1 | F37: =COUNTIFS('M2 Proposal'!$H$5:$H$70,"*"&A37&"*",'M2 Proposal'!$E$5:$E$70,"R1") -> 4 | G37: =COUNTIFS('M2 Proposal'!$H$5:$H$70,"*"&A37&"*",'M2 Proposal'!$E$5:$E$70,"R2") -> 1 | H37: =COUNTIFS('M2 Proposal'!$H$5:$H$70,"*"&A37&"*",'M2 Proposal'!$E$5:$E$70,"R3") -> 0 | I37: =COUNTIFS('M2 Proposal'!$H$5:$H$70,"*"&A37&"*",'M2 Proposal'!$E$5:$E$70,"Beyond") -> 0 | J37: R1 catalogue safety_note · R2 manuals/system ratings
A38: DC-34 | B38: L5 Data | C38: Evidence log | D38: Data | E38: =IF(_xlfn.MINIFS('M2 Proposal'!$I$5:$I$70,'M2 Proposal'!$H$5:$H$70,"*"&A38&"*")=0,"–",INDEX({"R1","R2","R3","Beyond"},_xlfn.MINIFS('M2 Proposal'!$I$5:$I$70,'M2 Proposal'!$H$5:$H$70,"*"&A38&"*"))) -> R1 | F38: =COUNTIFS('M2 Proposal'!$H$5:$H$70,"*"&A38&"*",'M2 Proposal'!$E$5:$E$70,"R1") -> 2 | G38: =COUNTIFS('M2 Proposal'!$H$5:$H$70,"*"&A38&"*",'M2 Proposal'!$E$5:$E$70,"R2") -> 1 | H38: =COUNTIFS('M2 Proposal'!$H$5:$H$70,"*"&A38&"*",'M2 Proposal'!$E$5:$E$70,"R3") -> 1 | I38: =COUNTIFS('M2 Proposal'!$H$5:$H$70,"*"&A38&"*",'M2 Proposal'!$E$5:$E$70,"Beyond") -> 0 | J38: R1 rule + inputs + time · R2 sources/versions
A39: DC-35 | B39: L5 Data | C39: Stock & price source adapter | D39: Data | E39: =IF(_xlfn.MINIFS('M2 Proposal'!$I$5:$I$70,'M2 Proposal'!$H$5:$H$70,"*"&A39&"*")=0,"–",INDEX({"R1","R2","R3","Beyond"},_xlfn.MINIFS('M2 Proposal'!$I$5:$I$70,'M2 Proposal'!$H$5:$H$70,"*"&A39&"*"))) -> R1 | F39: =COUNTIFS('M2 Proposal'!$H$5:$H$70,"*"&A39&"*",'M2 Proposal'!$E$5:$E$70,"R1") -> 3 | G39: =COUNTIFS('M2 Proposal'!$H$5:$H$70,"*"&A39&"*",'M2 Proposal'!$E$5:$E$70,"R2") -> 1 | H39: =COUNTIFS('M2 Proposal'!$H$5:$H$70,"*"&A39&"*",'M2 Proposal'!$E$5:$E$70,"R3") -> 1 | I39: =COUNTIFS('M2 Proposal'!$H$5:$H$70,"*"&A39&"*",'M2 Proposal'!$E$5:$E$70,"Beyond") -> 0 | J39: R1 static mock · R2 freshness/stale · R3 retailer API
A40: DC-36 | B40: Cross-cutting | C40: Labelling & i18n | D40: Code | E40: =IF(_xlfn.MINIFS('M2 Proposal'!$I$5:$I$70,'M2 Proposal'!$H$5:$H$70,"*"&A40&"*")=0,"–",INDEX({"R1","R2","R3","Beyond"},_xlfn.MINIFS('M2 Proposal'!$I$5:$I$70,'M2 Proposal'!$H$5:$H$70,"*"&A40&"*"))) -> R1 | F40: =COUNTIFS('M2 Proposal'!$H$5:$H$70,"*"&A40&"*",'M2 Proposal'!$E$5:$E$70,"R1") -> 2 | G40: =COUNTIFS('M2 Proposal'!$H$5:$H$70,"*"&A40&"*",'M2 Proposal'!$E$5:$E$70,"R2") -> 0 | H40: =COUNTIFS('M2 Proposal'!$H$5:$H$70,"*"&A40&"*",'M2 Proposal'!$E$5:$E$70,"R3") -> 0 | I40: =COUNTIFS('M2 Proposal'!$H$5:$H$70,"*"&A40&"*",'M2 Proposal'!$E$5:$E$70,"Beyond") -> 0 | J40: R1 DE default + EN toggle · R2 bilingual tests
A41: DC-37 | B41: Cross-cutting | C41: Security & privacy | D41: Code | E41: =IF(_xlfn.MINIFS('M2 Proposal'!$I$5:$I$70,'M2 Proposal'!$H$5:$H$70,"*"&A41&"*")=0,"–",INDEX({"R1","R2","R3","Beyond"},_xlfn.MINIFS('M2 Proposal'!$I$5:$I$70,'M2 Proposal'!$H$5:$H$70,"*"&A41&"*"))) -> R1 | F41: =COUNTIFS('M2 Proposal'!$H$5:$H$70,"*"&A41&"*",'M2 Proposal'!$E$5:$E$70,"R1") -> 2 | G41: =COUNTIFS('M2 Proposal'!$H$5:$H$70,"*"&A41&"*",'M2 Proposal'!$E$5:$E$70,"R2") -> 0 | H41: =COUNTIFS('M2 Proposal'!$H$5:$H$70,"*"&A41&"*",'M2 Proposal'!$E$5:$E$70,"R3") -> 0 | I41: =COUNTIFS('M2 Proposal'!$H$5:$H$70,"*"&A41&"*",'M2 Proposal'!$E$5:$E$70,"Beyond") -> 0 | J41: R1 key off client, no login · R3 full security review
...

Sheet M2 Release Plan
A1: Method 2 – Release plan, counts and V-model exit gates
A2: All counts are formulas over M2 Proposal / M2 Components by Release
B4: R1 – MVP / Pitch demo | C4: R2 – Extended MVP | D4: R3 – Pilot-ready
A5: Goal | B5: One safe end-to-end flow: describe project → max. 3 questions → validated shopping list with price, stock, aisle | C5: Make the plan richer and reusable: explanations, alternatives, owned items, offline checklist, assembly guide | D5: Prepare a store pilot: photo & voice entry, real store data, store search, scanner, associate hand-off
A6: Timeframe | B6: 2-week sprint, 19 Oct – ~1 Nov 2026 (built) | C6: After the course (roadmap) | D6: After R2 (roadmap)
A7: Use cases | B7: UC-1 hang 20 kg shelf · UC-3 hang picture/mirror · UC-5 high-risk refusal | C7: + UC-2 freestanding furniture · UC-4 paint a room | D7: + photo-based part identification
A8: Architecture focus | B8: Walking skeleton through all 5 layers: UI, orchestrator, intake/clarification/planner agents, gates G0–G4 + rule engine, CSV data | C8: Widen L1/L4/L5: explanation generator, alternatives calculator, owned-item reconciler, manufacturer data, offline PWA | D8: Add new inputs and integrations: vision agent, voice, scanner, store search, retailer adapter, monitoring, full security
A9: Verification (exit gate) | B9: Release-blocking tests in R1 pass (see count below) + unit tests of rule engine | C9: R1 tests re-run (regression) + R2 tests | D9: All release-blocking tests except Beyond
A10: Validation KPI | B10: 0 % hallucinated products · 100 % high-risk refusal · list < 5 s · ≥ 4/5 users finish in < 2 min | C10: BOM completeness ≥ 90 % on 5-10 templates | D10: Pilot: 50-100 consented projects, variant precision ≥ 95 %
A12: Requirements per release (by type)
A13: Type | B13: R1 | C13: R2 | D13: R3 | E13: Beyond
A14: Functional | B14: =COUNTIFS('M2 Proposal'!$B$5:$B$70,$A14,'M2 Proposal'!$E$5:$E$70,"R1") -> 10 | C14: =COUNTIFS('M2 Proposal'!$B$5:$B$70,$A14,'M2 Proposal'!$E$5:$E$70,"R2") -> 6 | D14: =COUNTIFS('M2 Proposal'!$B$5:$B$70,$A14,'M2 Proposal'!$E$5:$E$70,"R3") -> 6 | E14: =COUNTIFS('M2 Proposal'!$B$5:$B$70,$A14,'M2 Proposal'!$E$5:$E$70,"Beyond") -> 2
A15: Safety | B15: =COUNTIFS('M2 Proposal'!$B$5:$B$70,$A15,'M2 Proposal'!$E$5:$E$70,"R1") -> 10 | C15: =COUNTIFS('M2 Proposal'!$B$5:$B$70,$A15,'M2 Proposal'!$E$5:$E$70,"R2") -> 0 | D15: =COUNTIFS('M2 Proposal'!$B$5:$B$70,$A15,'M2 Proposal'!$E$5:$E$70,"R3") -> 0 | E15: =COUNTIFS('M2 Proposal'!$B$5:$B$70,$A15,'M2 Proposal'!$E$5:$E$70,"Beyond") -> 0
A16: Non-functional | B16: =COUNTIFS('M2 Proposal'!$B$5:$B$70,$A16,'M2 Proposal'!$E$5:$E$70,"R1") -> 9 | C16: =COUNTIFS('M2 Proposal'!$B$5:$B$70,$A16,'M2 Proposal'!$E$5:$E$70,"R2") -> 1 | D16: =COUNTIFS('M2 Proposal'!$B$5:$B$70,$A16,'M2 Proposal'!$E$5:$E$70,"R3") -> 1 | E16: =COUNTIFS('M2 Proposal'!$B$5:$B$70,$A16,'M2 Proposal'!$E$5:$E$70,"Beyond") -> 0
A17: Data | B17: =COUNTIFS('M2 Proposal'!$B$5:$B$70,$A17,'M2 Proposal'!$E$5:$E$70,"R1") -> 6 | C17: =COUNTIFS('M2 Proposal'!$B$5:$B$70,$A17,'M2 Proposal'!$E$5:$E$70,"R2") -> 1 | D17: =COUNTIFS('M2 Proposal'!$B$5:$B$70,$A17,'M2 Proposal'!$E$5:$E$70,"R3") -> 0 | E17: =COUNTIFS('M2 Proposal'!$B$5:$B$70,$A17,'M2 Proposal'!$E$5:$E$70,"Beyond") -> 0
A18: Release-blocking test | B18: =COUNTIFS('M2 Proposal'!$B$5:$B$70,$A18,'M2 Proposal'!$E$5:$E$70,"R1") -> 8 | C18: =COUNTIFS('M2 Proposal'!$B$5:$B$70,$A18,'M2 Proposal'!$E$5:$E$70,"R2") -> 2 | D18: =COUNTIFS('M2 Proposal'!$B$5:$B$70,$A18,'M2 Proposal'!$E$5:$E$70,"R3") -> 3 | E18: =COUNTIFS('M2 Proposal'!$B$5:$B$70,$A18,'M2 Proposal'!$E$5:$E$70,"Beyond") -> 1
A19: Total | B19: =SUM(B14:B18) -> 43 | C19: =SUM(C14:C18) -> 10 | D19: =SUM(D14:D18) -> 10 | E19: =SUM(E14:E18) -> 3
A21: MoSCoW per release
A22: MoSCoW | B22: R1 | C22: R2 | D22: R3 | E22: Beyond
A23: Must | B23: =COUNTIFS('M2 Proposal'!$F$5:$F$70,$A23,'M2 Proposal'!$E$5:$E$70,"R1") -> 37 | C23: =COUNTIFS('M2 Proposal'!$F$5:$F$70,$A23,'M2 Proposal'!$E$5:$E$70,"R2") -> 3 | D23: =COUNTIFS('M2 Proposal'!$F$5:$F$70,$A23,'M2 Proposal'!$E$5:$E$70,"R3") -> 3 | E23: =COUNTIFS('M2 Proposal'!$F$5:$F$70,$A23,'M2 Proposal'!$E$5:$E$70,"Beyond") -> 0
A24: Should | B24: =COUNTIFS('M2 Proposal'!$F$5:$F$70,$A24,'M2 Proposal'!$E$5:$E$70,"R1") -> 6 | C24: =COUNTIFS('M2 Proposal'!$F$5:$F$70,$A24,'M2 Proposal'!$E$5:$E$70,"R2") -> 5 | D24: =COUNTIFS('M2 Proposal'!$F$5:$F$70,$A24,'M2 Proposal'!$E$5:$E$70,"R3") -> 4 | E24: =COUNTIFS('M2 Proposal'!$F$5:$F$70,$A24,'M2 Proposal'!$E$5:$E$70,"Beyond") -> 0
A25: Could | B25: =COUNTIFS('M2 Proposal'!$F$5:$F$70,$A25,'M2 Proposal'!$E$5:$E$70,"R1") -> 0 | C25: =COUNTIFS('M2 Proposal'!$F$5:$F$70,$A25,'M2 Proposal'!$E$5:$E$70,"R2") -> 2 | D25: =COUNTIFS('M2 Proposal'!$F$5:$F$70,$A25,'M2 Proposal'!$E$5:$E$70,"R3") -> 3 | E25: =COUNTIFS('M2 Proposal'!$F$5:$F$70,$A25,'M2 Proposal'!$E$5:$E$70,"Beyond") -> 0
A26: Won't | B26: =COUNTIFS('M2 Proposal'!$F$5:$F$70,$A26,'M2 Proposal'!$E$5:$E$70,"R1") -> 0 | C26: =COUNTIFS('M2 Proposal'!$F$5:$F$70,$A26,'M2 Proposal'!$E$5:$E$70,"R2") -> 0 | D26: =COUNTIFS('M2 Proposal'!$F$5:$F$70,$A26,'M2 Proposal'!$E$5:$E$70,"R3") -> 0 | E26: =COUNTIFS('M2 Proposal'!$F$5:$F$70,$A26,'M2 Proposal'!$E$5:$E$70,"Beyond") -> 3
A27: Must share | B27: =IFERROR(B23/SUM(B23:B26),0) -> 0.86046512 | C27: =IFERROR(C23/SUM(C23:C26),0) -> 0.3 | D27: =IFERROR(D23/SUM(D23:D26),0) -> 0.3 | E27: Target ≈ 60 % (DSDM guideline); R1 is higher because safety is fixed Must
A29: Design components first needed (by layer)
A30: Layer | B30: R1 | C30: R2 | D30: R3 | E30: Beyond
A31: L1 Presentation | B31: =COUNTIFS('M2 Components by Release'!$B$5:$B$45,$A31,'M2 Components by Release'!$E$5:$E$45,"R1") -> 5 | C31: =COUNTIFS('M2 Components by Release'!$B$5:$B$45,$A31,'M2 Components by Release'!$E$5:$E$45,"R2") -> 3 | D31: =COUNTIFS('M2 Components by Release'!$B$5:$B$45,$A31,'M2 Components by Release'!$E$5:$E$45,"R3") -> 4 | E31: =COUNTIFS('M2 Components by Release'!$B$5:$B$45,$A31,'M2 Components by Release'!$E$5:$E$45,"Beyond") -> 0
A32: L2 Application | B32: =COUNTIFS('M2 Components by Release'!$B$5:$B$45,$A32,'M2 Components by Release'!$E$5:$E$45,"R1") -> 4 | C32: =COUNTIFS('M2 Components by Release'!$B$5:$B$45,$A32,'M2 Components by Release'!$E$5:$E$45,"R2") -> 0 | D32: =COUNTIFS('M2 Components by Release'!$B$5:$B$45,$A32,'M2 Components by Release'!$E$5:$E$45,"R3") -> 0 | E32: =COUNTIFS('M2 Components by Release'!$B$5:$B$45,$A32,'M2 Components by Release'!$E$5:$E$45,"Beyond") -> 0
A33: L3 AI (proposes) | B33: =COUNTIFS('M2 Components by Release'!$B$5:$B$45,$A33,'M2 Components by Release'!$E$5:$E$45,"R1") -> 3 | C33: =COUNTIFS('M2 Components by Release'!$B$5:$B$45,$A33,'M2 Components by Release'!$E$5:$E$45,"R2") -> 1 | D33: =COUNTIFS('M2 Components by Release'!$B$5:$B$45,$A33,'M2 Components by Release'!$E$5:$E$45,"R3") -> 1 | E33: =COUNTIFS('M2 Components by Release'!$B$5:$B$45,$A33,'M2 Components by Release'!$E$5:$E$45,"Beyond") -> 0
A34: L4 Control (decides) | B34: =COUNTIFS('M2 Components by Release'!$B$5:$B$45,$A34,'M2 Components by Release'!$E$5:$E$45,"R1") -> 7 | C34: =COUNTIFS('M2 Components by Release'!$B$5:$B$45,$A34,'M2 Components by Release'!$E$5:$E$45,"R2") -> 1 | D34: =COUNTIFS('M2 Components by Release'!$B$5:$B$45,$A34,'M2 Components by Release'!$E$5:$E$45,"R3") -> 0 | E34: =COUNTIFS('M2 Components by Release'!$B$5:$B$45,$A34,'M2 Components by Release'!$E$5:$E$45,"Beyond") -> 0
A35: L5 Data | B35: =COUNTIFS('M2 Components by Release'!$B$5:$B$45,$A35,'M2 Components by Release'!$E$5:$E$45,"R1") -> 6 | C35: =COUNTIFS('M2 Components by Release'!$B$5:$B$45,$A35,'M2 Components by Release'!$E$5:$E$45,"R2") -> 0 | D35: =COUNTIFS('M2 Components by Release'!$B$5:$B$45,$A35,'M2 Components by Release'!$E$5:$E$45,"R3") -> 0 | E35: =COUNTIFS('M2 Components by Release'!$B$5:$B$45,$A35,'M2 Components by Release'!$E$5:$E$45,"Beyond") -> 0
A36: Cross-cutting | B36: =COUNTIFS('M2 Components by Release'!$B$5:$B$45,$A36,'M2 Components by Release'!$E$5:$E$45,"R1") -> 4 | C36: =COUNTIFS('M2 Components by Release'!$B$5:$B$45,$A36,'M2 Components by Release'!$E$5:$E$45,"R2") -> 0 | D36: =COUNTIFS('M2 Components by Release'!$B$5:$B$45,$A36,'M2 Components by Release'!$E$5:$E$45,"R3") -> 2 | E36: =COUNTIFS('M2 Components by Release'!$B$5:$B$45,$A36,'M2 Components by Release'!$E$5:$E$45,"Beyond") -> 0
A37: Total | B37: =SUM(B31:B36) -> 29 | C37: =SUM(C31:C36) -> 5 | D37: =SUM(D31:D36) -> 7 | E37: =SUM(E31:E36) -> 0
